Workbook

Sheet Lies mich
A1: Safaitic — Gedichtband: Arbeitsmaterial
A3: Zweck: literarische, verknappte, klanghafte Auswahl; verankert, nicht wissenschaftlich.
A4: Die Auswahl ist kuratiert und sagt damit auch über uns etwas aus, nicht nur über die Steppe.
A6: Blätter:
A7: • Shortlist (kuratiert) — entkernte, jahresbogen-sortierte Auswahl als Bandgerüst.
A8: • Longlist (gerankt) — alle 2.451 Inschriften mit Score-Bausteinen.
A9: • Gewichtung — hier Gewichte ändern; LiteraryScore rechnet in der Longlist neu.
A11: Score-Bausteine:
A12: emo=Affekt, scene=konkretes Bild, rarity=Seltenheit des Themas, meta=Fluch/Schrift-Selbstbezug,
A13: anchor=Jahr/König (Verankerung), brevity=verknappte Dichte, integrity=wenig Lücken (----),
A14: clarity=wenig unsichere Lesung ({ }/[ ]), geneal_pen=Abzug für lange Ahnenketten.
A16: Refrain=1: enthält Fluch-/Segensformel — als wiederkehrendes Motiv im Band nutzbar.
A17: Hinweis: Übersetzungen aus OCIANA (englisch). Deutsche Nachdichtung ist ein weiterer Schritt.

Sheet Shortlist (kuratiert)
A1: # | B1: Phase (Jahresbogen) | C1: Refrain | D1: Score | E1: Thema | F1: Übersetzung (OCIANA) | G1: Fundort | H1: ID | I1: URL
A2: 1 | B2: Dürre & Lager | C2: 0 | D2: 20.86 | E2: Dry Season & Camping; Grief & Mourning | F2: By Qnf son of Db son of Qmr son of Ḥy and he spent the season of the later rains in this valley [and] he wept with grief for a loved one (or for Ḥbb) | G2: Wādī Sārah, Al-Mafraq Province, Jordan | H2: SSWS 6 | I2: http://krc.orient.ox.ac.uk/ociana/corpus/pages/OCIANA_0031082.html
A3: 1 | B3: Dürre & Lager | C3: 0 | D3: 15.29 | E3: Dry Season & Camping | F3: By ʿqrb and he pastured and it rained and he spent the season of the later rains | G3: Al-ʿUwayṣ¡ | H3: NSR 64.2 | I3: http://krc.orient.ox.ac.uk/ociana/corpus/pages/OCIANA_0010417.html
A4: 1 | B4: Dürre & Lager | C4: 0 | D4: 15.02 | E4: Dry Season & Camping | F4: By Ḫbn son of Ḫlf son of Ḫlf {son of} {s²gʾ} {and} he spent the season of the later rains and he pastured and camped and grieved for ʾsd | G4: In Ghad¡r Budayna on the slopes of the nearby hillside of Ruṣayfa (?) | H4: NSR 34.1 | I4: http://krc.orient.ox.ac.uk/ociana/corpus/pages/OCIANA_0010369.html
A5: 1 | B5: Dürre & Lager | C5: 0 | D5: 14.19 | E5: Dry Season & Camping; Watching & Scouting | F5: By ʿmy son of S¹lm and he pastured the inner desert and so he spent the season of the later rains and he spent the dry season on Lṯ and he was on the look-out for the horses | G5: EDS 80-5 | H5: CEDS 230 | I5: http://krc.orient.ox.ac.uk/ociana/corpus/pages/OCIANA_0018862.html
A6: 1 | B6: Dürre & Lager | C6: 0 | D6: 13.89 | E6: Dry Season & Camping; Journey & Travel; Fear & Anxiety | F6: By ʾs¹ {son of} ʾs¹d son of Rbʾl son of ʾnʿm son of Ms¹k son of S²kr son of Ġlmt son of ʿbd and {he came to a watering place} in an area of abundant herbage and remained ---- and the winter brought no rain the year Wdn fled from {Rmn}----? and so O Bʿls¹mn [grant] relief from distress and uncertainty | G6: Al-ʿĪsāwī, Rif Dimašq, Syria | H6: Is.Mu 88 | I6: http://krc.orient.ox.ac.uk/ociana/corpus/pages/OCIANA_0027093.html
A7: 1 | B7: Dürre & Lager | C7: 0 | D7: 13.79 | E7: Dry Season & Camping; Fear & Anxiety | F7: By ʾnʿm son of Zbdhm and he camped near water and grieved and was in need of aid | G7: Wādī Salma, Al-Mafraq Province, Jordan | H7: RWQ 117 | I7: http://krc.orient.ox.ac.uk/ociana/corpus/pages/OCIANA_0032045.html
A8: 1 | B8: Dürre & Lager | C8: 0 | D8: 13.7 | E8: Dry Season & Camping | F8: By Ḫlʾl [son of] S²mt son of {Ḃnt} son of Ḫlʾl son of Ḃnt and he grieved for {ʿbd} {and} {for} ʾnʿm and for ʿbṯn and for {Mlk} and for ʿd and ʿl- Ḥb {and} he spent the season of the later rains at this watering hole in [the month of S¹bṭ(). | G8: Riǧm Qaʿqūl, Rif Dimashq, Syria | H8: C 1156 | I8: http://krc.orient.ox.ac.uk/ociana/corpus/pages/OCIANA_0004579.html
A9: 1 | B9: Dürre & Lager | C9: 0 | D9: 13.52 | E9: Dry Season & Camping | F9: By Mlk son of Tm son of Mlk son of Tm son of Mḥlm son of Tm son of Nkf son of Ṣʾr son of ʿbṭ son of Qnʾl son of {S¹rʾ} of the lineage of Ṣʾr and he migrated to the inner desert with some goats and then spent the season of the later rains on the slopes of this wādī. | G9: On the left bank of Wādī al-Gharz, near a bridge to the track leading from Damascus to Zalaf (C p. 589), Al-Suwaydah or Rif Dimashq, Syria | H9: C 4772 | I9: http://krc.orient.ox.ac.uk/ociana/corpus/pages/OCIANA_0007976.html
A10: 1 | B10: Dürre & Lager | C10: 0 | D10: 13.5 | E10: Dry Season & Camping | F10: By {S²ll} son of Gmr and he was distraught with grief for S²r son of Hbdw and he camped here near permanent water | G10: "Between al-Ḥifnah and Abū Zaʿrūr" (C p. 495), Al-Suwaydah, Syria | H10: C 3962 | I10: http://krc.orient.ox.ac.uk/ociana/corpus/pages/OCIANA_0007166.html
A11: 1 | B11: Dürre & Lager | C11: 0 | D11: 13.49 | E11: Dry Season & Camping | F11: By Ḍb son of Ḫlfn son of Ms¹k son of Dd son of Dgg and he grieved for Rbḥ and he camped near a permanent source of water and he grieved for his companions | G11: Wādī Salma, Al-Mafraq Province, Jordan | H11: AbSWS 21 | I11: http://krc.orient.ox.ac.uk/ociana/corpus/pages/OCIANA_0030474.html
A12: 1 | B12: Dürre & Lager | C12: 0 | D12: 13.19 | E12: Dry Season & Camping | F12: By Qdm son of Bnmty son of Qdm and he camped here while migrating to the inner desert and he was devastated with grief for Ṣrmt | G12: Zalaf (f) "In the neighbourhood of Zalaf, on the west side of the track leading to Damascus " (C p. 291)., Rif Dimashq, Syria | H12: C 2240 | I12: http://krc.orient.ox.ac.uk/ociana/corpus/pages/OCIANA_0005444.html
A13: 1 | B13: Dürre & Lager | C13: 1 | D13: 13.12 | E13: Dry Season & Camping; Grief & Mourning | F13: By S¹ḫr son of ʿbd son of ʾdm son of Ms¹k son of S²rb and he remembered Ḍr and wept [for] his father and [for] ʿbd and his paternal uncle and so he was distraught over those who were harmed and were lost; and he spent the winter in the Ḥarrah again and camped in this place; and may he who would efface this writing have scabies and be thrown from the grave. | G13: Tall aḍ-Ḍabiʿ/ Tall aḍ-Ḍbēʿah/ Wādī as-Samin- , Syria | H13: RSIS 351 | I13: http://krc.orient.ox.ac.uk/ociana/corpus/pages/OCIANA_0032974.html
... A151: 12 | B151: Verankerung (Jahr & König) | C151: 0 | D151: 13.78 | E151: Historical Event | F151: By Qḥs² son of Ys¹lm son of ʿwḏn son of Mlk and {he pastured} [in] the year of drought w r---- and so O S²qm make him secure from misfortune | G151: Al-Mafraq, Jordan | H151: KRS 1009 | I151: http://krc.orient.ox.ac.uk/ociana/corpus/pages/OCIANA_0021637.html

Sheet Gewichtung
A1: Baustein | B1: Gewicht
A2: emo | B2: 3
A3: scene | B3: 2.5
A4: rarity | B4: 3
A5: meta | B5: 1.5
A6: anchor | B6: 1
A7: brevity | B7: 2.5
A8: integrity | B8: 2
A9: clarity | B9: 1.5
A10: geneal_pen | B10: -2

Sheet Longlist (gerankt)
A1: LiteraryScore | B1: emo | C1: scene | D1: rarity | E1: meta | F1: anchor | G1: brevity | H1: integrity | I1: clarity | J1: geneal_pen | K1: Theme | L1: Arc | M1: Refrain | N1: core_words | O1: lacuna | P1: Translation | Q1: Location | R1: Inscription ID | S1: URL
A2: =B2*Gewichtung!$B$2+C2*Gewichtung!$B$3+D2*Gewichtung!$B$4+E2*Gewichtung!$B$5+F2*Gewichtung!$B$6+G2*Gewichtung!$B$7+H2*Gewichtung!$B$8+I2*Gewichtung!$B$9+J2*Gewichtung!$B$10 -> 27.4 | B2: 3 | C2: 4 | D2: 0.85 | E2: 0 | F2: 2 | G2: 0.3 | H2: 1 | I2: 1 | J2: 0.2 | K2: Disease & Injury; Death & Murder; Journey & Travel; Historical Event | L2: Krankheit & Versehrung | M2: 0 | N2: 54 | O2: 0 | P2: By Rbʾl son of Ḥnn son of Ẓʿn son of H̲yḏ son of ʿḏr and he went to water cautious of drought, then (again) in Aquarius, then Aries, then Libra, and then Libra (again, i.e. for two years in a row), during which he grieved in pain for a loved one and for the camels, which he pastured, having migrated from the inner desert, the year Bnt died. | Q2: Wādī Sārah/ Ganūb Wādī Sārahʿabd, Al-Mafraq Province, Jordan | R2: ASWS 73 | S2: http://krc.orient.ox.ac.uk/ociana/corpus/pages/OCIANA_0031628.html
A3: =B3*Gewichtung!$B$2+C3*Gewichtung!$B$3+D3*Gewichtung!$B$4+E3*Gewichtung!$B$5+F3*Gewichtung!$B$6+G3*Gewichtung!$B$7+H3*Gewichtung!$B$8+I3*Gewichtung!$B$9+J3*Gewichtung!$B$10 -> 20.855 | B3: 4 | C3: 1 | D3: 0.63 | E3: 0 | F3: 0 | G3: 0.6 | H3: 1 | I3: 0.91 | J3: 0.2 | K3: Dry Season & Camping; Grief & Mourning | L3: Dürre & Lager | M3: 0 | N3: 24 | O3: 0 | P3: By Qnf son of Db son of Qmr son of Ḥy and he spent the season of the later rains in this valley [and] he wept with grief for a loved one (or for Ḥbb) | Q3: Wādī Sārah, Al-Mafraq Province, Jordan | R3: SSWS 6 | S3: http://krc.orient.ox.ac.uk/ociana/corpus/pages/OCIANA_0031082.html
A4: =B4*Gewichtung!$B$2+C4*Gewichtung!$B$3+D4*Gewichtung!$B$4+E4*Gewichtung!$B$5+F4*Gewichtung!$B$6+G4*Gewichtung!$B$7+H4*Gewichtung!$B$8+I4*Gewichtung!$B$9+J4*Gewichtung!$B$10 -> 20.72 | B4: 4 | C4: 0 | D4: 0.94 | E4: 0 | F4: 0 | G4: 1 | H4: 1 | I4: 1 | J4: 0.05 | K4: Grief & Mourning | L4: Klage | M4: 0 | N4: 9 | O4: 0 | P4: By S²kr son of Hf and he wept with grief for his loved one | Q4: Site 12 | R4: AbaNS 361 | S4: http://krc.orient.ox.ac.uk/ociana/corpus/pages/OCIANA_0025126.html
A5: =B5*Gewichtung!$B$2+C5*Gewichtung!$B$3+D5*Gewichtung!$B$4+E5*Gewichtung!$B$5+F5*Gewichtung!$B$6+G5*Gewichtung!$B$7+H5*Gewichtung!$B$8+I5*Gewichtung!$B$9+J5*Gewichtung!$B$10 -> 20.405 | B5: 4 | C5: 0 | D5: 0.94 | E5: 0 | F5: 0 | G5: 1 | H5: 1 | I5: 0.79 | J5: 0.05 | K5: Grief & Mourning | L5: Klage | M5: 0 | N5: 9 | O5: 0 | P5: By {Fʾrn} son of Ṯʿr and he wept with grief for his loved one | Q5: — | R5: WH 2472 | S5: http://krc.orient.ox.ac.uk/ociana/corpus/pages/OCIANA_0013353.html
A6: =B6*Gewichtung!$B$2+C6*Gewichtung!$B$3+D6*Gewichtung!$B$4+E6*Gewichtung!$B$5+F6*Gewichtung!$B$6+G6*Gewichtung!$B$7+H6*Gewichtung!$B$8+I6*Gewichtung!$B$9+J6*Gewichtung!$B$10 -> 20.35 | B6: 4 | C6: 0 | D6: 0.94 | E6: 0 | F6: 0 | G6: 1 | H6: 1 | I6: 0.82 | J6: 0.1 | K6: Grief & Mourning | L6: Klage | M6: 0 | N6: 9 | O6: 0 | P6: By Ġlm son of S¹ʿdʾl son of {Dgn} and he wept with grief for his loved one | Q6: wadī and biyār al-ghuṣayn, Jordan | R6: KhBG 344 | S6: http://krc.orient.ox.ac.uk/ociana/corpus/pages/OCIANA_0018225.html
A7: =B7*Gewichtung!$B$2+C7*Gewichtung!$B$3+D7*Gewichtung!$B$4+E7*Gewichtung!$B$5+F7*Gewichtung!$B$6+G7*Gewichtung!$B$7+H7*Gewichtung!$B$8+I7*Gewichtung!$B$9+J7*Gewichtung!$B$10 -> 19.73 | B7: 1 | C7: 3 | D7: 0.85 | E7: 0 | F7: 2 | G7: 0.6 | H7: 1 | I7: 0.92 | J7: 0.1 | K7: Disease & Injury | L7: Krankheit & Versehrung | M7: 0 | N7: 30 | O7: 0 | P7: By ʾnʿm son of ʾnf son of Grmʾl and he found the inscription of ʾnʿm, so he grieved in pain [for him] and he pastured the camels the year in which the Nabataeans passed by this watering place | Q7: Ruǧm al-Ḥifnah, Al-Suweidah, Syria | R7: LP 4 | S7: http://krc.orient.ox.ac.uk/ociana/corpus/pages/OCIANA_0008588.html
A8: =B8*Gewichtung!$B$2+C8*Gewichtung!$B$3+D8*Gewichtung!$B$4+E8*Gewichtung!$B$5+F8*Gewichtung!$B$6+G8*Gewichtung!$B$7+H8*Gewichtung!$B$8+I8*Gewichtung!$B$9+J8*Gewichtung!$B$10 -> 19.065 | B8: 4 | C8: 0 | D8: 0.92 | E8: 0 | F8: 0 | G8: 0.6 | H8: 1 | I8: 0.87 | J8: 0.25 | K8: Journey & Travel | L8: Wege & Wasser | M8: 0 | N8: 30 | O8: 0 | P8: By {Wrd} son of ʾḏnt son of S²rk son of ʾḏnt son of Wrd son of Nġbr and he returned to a place of water and the journey lasted as far as Ḥawrān, and so he longed for a loved one and grieved for Mḥlm and {Ḥnqt}. | Q8: Ǧabal Says, Rif Dimashq, Syria | R8: C 99 | S8: http://krc.orient.ox.ac.uk/ociana/corpus/pages/OCIANA_0003304.html
A9: =B9*Gewichtung!$B$2+C9*Gewichtung!$B$3+D9*Gewichtung!$B$4+E9*Gewichtung!$B$5+F9*Gewichtung!$B$6+G9*Gewichtung!$B$7+H9*Gewichtung!$B$8+I9*Gewichtung!$B$9+J9*Gewichtung!$B$10 -> 18.95 | B9: 1 | C9: 4 | D9: 0 | E9: 0 | F9: 2 | G9: 0.3 | H9: 1 | I9: 1 | J9: 0.15 | K9: Pastoral & Herding | L9: Weide & Herde | M9: 0 | N9: 46 | O9: 0 | P9: By Ṣḥb son of Bʿr son of Zbdʾl son of S²mt and he grieved for his brother struck down by Fate and he returned to water from the inner desert the sheep being emaciated the year the king's caravan starved in sloping ground rising from a valley up to the face of a mountain for two months | Q9: Zalaf (k) "On the left bank of Wādī al-Shām, about 3 km upstream towards Zalaf" (C p. 381)., Rif Dimashq, Syria | R9: C 3064 | S9: http://krc.orient.ox.ac.uk/ociana/corpus/pages/OCIANA_0006268.html
A10: =B10*Gewichtung!$B$2+C10*Gewichtung!$B$3+D10*Gewichtung!$B$4+E10*Gewichtung!$B$5+F10*Gewichtung!$B$6+G10*Gewichtung!$B$7+H10*Gewichtung!$B$8+I10*Gewichtung!$B$9+J10*Gewichtung!$B$10 -> 18.91 | B10: 3 | C10: 0 | D10: 0.94 | E10: 2 | F10: 0 | G10: 0.6 | H10: 1 | I10: 0.86 | J10: 0.35 | K10: Grief & Mourning | L10: Klage | M10: 1 | N10: 40 | O10: 0 | P10: By ʿḏ son of Ġṯ son of ʿḏ son of ʿḏ son of Ġṯ son of Wdm son of {S¹r} son of Ṣbḥ and Bky and he {wept} and grieved for his father, who was murdered, so, O Lh, he will have vengeance; and he longed for his paternal uncle and all of his companions; and may he who would {efface} go blind | Q10: Al-Mrōshan, Al-Suweidah, Syria | R10: LP 243 | S10: http://krc.orient.ox.ac.uk/ociana/corpus/pages/OCIANA_0008827.html
A11: =B11*Gewichtung!$B$2+C11*Gewichtung!$B$3+D11*Gewichtung!$B$4+E11*Gewichtung!$B$5+F11*Gewichtung!$B$6+G11*Gewichtung!$B$7+H11*Gewichtung!$B$8+I11*Gewichtung!$B$9+J11*Gewichtung!$B$10 -> 18.47 | B11: 3 | C11: 0 | D11: 0.89 | E11: 0 | F11: 1 | G11: 1 | H11: 1 | I11: 1 | J11: 0.1 | K11: Death & Murder | L11: Tod & Gewalt | M11: 0 | N11: 12 | O11: 0 | P11: By H̲wf son of ʿds¹ son of Mlkt and he grieved for a loved one the year Mʿz was killed | Q11: Cairn 9 | R11: HaNSB 335 | S11: http://krc.orient.ox.ac.uk/ociana/corpus/pages/OCIANA_0019620.html
A12: =B12*Gewichtung!$B$2+C12*Gewichtung!$B$3+D12*Gewichtung!$B$4+E12*Gewichtung!$B$5+F12*Gewichtung!$B$6+G12*Gewichtung!$B$7+H12*Gewichtung!$B$8+I12*Gewichtung!$B$9+J12*Gewichtung!$B$10 -> 18.37 | B12: 3 | C12: 1 | D12: 0.94 | E12: 0 | F12: 1 | G12: 0.3 | H12: 0.75 | I12: 0.8 | J12: 0.2 | K12: Grief & Mourning; Historical Event | L12: Klage | M12: 0 | N12: 46 | O12: 1 | P12: By Ngʾt son of Yʿly son of Bny {son of} S²ʿ son of Qmlt and he found the writing of Ms¹k and he wept and was overshadowed by grief and {he remembered} his brother {taken captive} the year of the struggle of ʾl Mʿṣ and he grieved for Rb and for Yʿly and for {----ḥ} and so he became depressed | Q12: Wādī Salma, Al-Mafraq Province, Jordan | R12: KRS 17 | S12: http://krc.orient.ox.ac.uk/ociana/corpus/pages/OCIANA_0020645.html
A13: =B13*Gewichtung!$B$2+C13*Gewichtung!$B$3+D13*Gewichtung!$B$4+E13*Gewichtung!$B$5+F13*Gewichtung!$B$6+G13*Gewichtung!$B$7+H13*Gewichtung!$B$8+I13*Gewichtung!$B$9+J13*Gewichtung!$B$10 -> 18.37 | B13: 1 | C13: 3 | D13: 0.99 | E13: 0 | F13: 0 | G13: 0.6 | H13: 1 | I13: 1 | J13: 0.05 | K13: Fear & Anxiety | L13: Angst | M13: 0 | N13: 26 | O13: 0 | P13: By Whblh son of ʿbdʾl and he pastured the water course whilst migrating with the tribe and he was afraid h --- Ḏs²r may he be secure and relieved from adversity | Q13: Al-Mafraq, Jordan | R13: KRS 1949 | S13: http://krc.orient.ox.ac.uk/ociana/corpus/pages/OCIANA_0022578.html
... A1407: =B1407*Gewichtung!$B$2+C1407*Gewichtung!$B$3+D1407*Gewichtung!$B$4+E1407*Gewichtung!$B$5+F1407*Gewichtung!$B$6+G1407*Gewichtung!$B$7+H1407*Gewichtung!$B$8+I1407*Gewichtung!$B$9+J1407*Gewichtung!$B$10 -> 7.755 | B1407: 0 | C1407: 0 | D1407: 0.78 | E1407: 0 | F1407: 0 | G1407: 1 | H1407: 1 | I1407: 0.81 | J1407: 0.15 | K1407: Watching & Scouting | L1407: Spähen & Warten | M1407: 0 | N1407: 5 | O1407: 0 | P1407: By ʾnʿm son of Wḍʾ son of Ḏʾbn son of Hbrt and {he was on watch} | Q1407: Tell Asada | R1407: MEG 4 | S1407: http://krc.orient.ox.ac.uk/ociana/corpus/pages/OCIANA_0010313.html
A1408: =B1408*Gewichtung!$B$2+C1408*Gewichtung!$B$3+D1408*Gewichtung!$B$4+E1408*Gewichtung!$B$5+F1408*Gewichtung!$B$6+G1408*Gewichtung!$B$7+H1408*Gewichtung!$B$8+I1408*Gewichtung!$B$9+J1408*Gewichtung!$B$10 -> 7.765 | B1408: 0 | C1408: 0 | D1408: 0.78 | E1408: 0 | F1408: 0 | G1408: 1 | H1408: 1 | I1408: 0.75 | J1408: 0.1 | K1408: Watching & Scouting | L1408: Spähen & Warten | M1408: 0 | N1408: 16 | O1408: 0 | P1408: By Ḥd son of Mḥrk son of Mty and he kept watch ʿ{n}{z}t h- gʿlt and so O Lt make safe those who remain | Q1408: Jordan | S1408: http://krc.orient.ox.ac.uk/ociana/corpus/pages/OCIANA_0034769.html
A1409: =B1409*Gewichtung!$B$2+C1409*Gewichtung!$B$3+D1409*Gewichtung!$B$4+E1409*Gewichtung!$B$5+F1409*Gewichtung!$B$6+G1409*Gewichtung!$B$7+H1409*Gewichtung!$B$8+I1409*Gewichtung!$B$9+J1409*Gewichtung!$B$10 -> 7.76 | B1409: 0 | C1409: 0 | D1409: 0.78 | E1409: 0 | F1409: 1 | G1409: 1 | H1409: 0.5 | I1409: 0.68 | J1409: 0.05 | K1409: Watching & Scouting; Historical Event | L1409: Spähen & Warten | M1409: 0 | N1409: 10 | O1409: 2 | P1409: {----ʾs¹} son of {----mʿl} of the lineage of Ḍf and he was on the look-out the year of Ḥs² | Q1409: WH Cairn 7 | R1409: WH 174 | S1409: http://krc.orient.ox.ac.uk/ociana/corpus/pages/OCIANA_0010928.html
A1410: =B1410*Gewichtung!$B$2+C1410*Gewichtung!$B$3+D1410*Gewichtung!$B$4+E1410*Gewichtung!$B$5+F1410*Gewichtung!$B$6+G1410*Gewichtung!$B$7+H1410*Gewichtung!$B$8+I1410*Gewichtung!$B$9+J1410*Gewichtung!$B$10 -> 7.76 | B1410: 0 | C1410: 0 | D1410: 0.92 | E1410: 0 | F1410: 0 | G1410: 0.6 | H1410: 1 | I1410: 1 | J1410: 0 | K1410: Journey & Travel | L1410: Wege & Wasser | M1410: 0 | N1410: 23 | O1410: 0 | P1410: Behold, there came a supplicant and visited this building, being a traveller of Ymmt, keeping off dangers, and he became a brother here | Q1410: Ṣanayim al-Gharz, Rif Dimashq, Syria | R1410: LP 1211 | S1410: http://krc.orient.ox.ac.uk/ociana/corpus/pages/OCIANA_0009795.html
A1411: =B1411*Gewichtung!$B$2+C1411*Gewichtung!$B$3+D1411*Gewichtung!$B$4+E1411*Gewichtung!$B$5+F1411*Gewichtung!$B$6+G1411*Gewichtung!$B$7+H1411*Gewichtung!$B$8+I1411*Gewichtung!$B$9+J1411*Gewichtung!$B$10 -> 7.75 | B1411: 0 | C1411: 1 | D1411: 0 | E1411: 0 | F1411: 0 | G1411: 1 | H1411: 1 | I1411: 0.5 | J1411: 0 | K1411: Pastoral & Herding | L1411: Weide & Herde | M1411: 0 | N1411: 5 | O1411: 0 | P1411: By {ʿtr} is the male camel | Q1411: Wādī Ḥafīr, ʿAqabah Governorate, Jordan | R1411: CH.R691 | S1411: http://krc.orient.ox.ac.uk/ociana/corpus/pages/OCIANA_0050668.html
A1412: =B1412*Gewichtung!$B$2+C1412*Gewichtung!$B$3+D1412*Gewichtung!$B$4+E1412*Gewichtung!$B$5+F1412*Gewichtung!$B$6+G1412*Gewichtung!$B$7+H1412*Gewichtung!$B$8+I1412*Gewichtung!$B$9+J1412*Gewichtung!$B$10 -> 7.75 | B1412: 0 | C1412: 1 | D1412: 0 | E1412: 0 | F1412: 0 | G1412: 1 | H1412: 1 | I1412: 0.5 | J1412: 0 | K1412: Pastoral & Herding | L1412: Weide & Herde | M1412: 0 | N1412: 5 | O1412: 0 | P1412: By {Mṣʿ} is the young she-camel | Q1412: Al-ʿĪsāwī, Rif Dimašq, Syria | R1412: Is.Mu 356 | S1412: http://krc.orient.ox.ac.uk/ociana/corpus/pages/OCIANA_0028428.html
A1413: =B1413*Gewichtung!$B$2+C1413*Gewichtung!$B$3+D1413*Gewichtung!$B$4+E1413*Gewichtung!$B$5+F1413*Gewichtung!$B$6+G1413*Gewichtung!$B$7+H1413*Gewichtung!$B$8+I1413*Gewichtung!$B$9+J1413*Gewichtung!$B$10 -> 7.75 | B1413: 0 | C1413: 1 | D1413: 0 | E1413: 0 | F1413: 0 | G1413: 1 | H1413: 1 | I1413: 0.5 | J1413: 0 | K1413: Pastoral & Herding | L1413: Weide & Herde | M1413: 0 | N1413: 5 | O1413: 0 | P1413: By {S¹ʿdt} is the young she-camel | Q1413: Al-ʿĪsāwī, Rif Dimašq, Syria | R1413: Is.H 569 | S1413: http://krc.orient.ox.ac.uk/ociana/corpus/pages/OCIANA_0028663.html
A1414: =B1414*Gewichtung!$B$2+C1414*Gewichtung!$B$3+D1414*Gewichtung!$B$4+E1414*Gewichtung!$B$5+F1414*Gewichtung!$B$6+G1414*Gewichtung!$B$7+H1414*Gewichtung!$B$8+I1414*Gewichtung!$B$9+J1414*Gewichtung!$B$10 -> 7.75 | B1414: 0 | C1414: 1 | D1414: 0 | E1414: 0 | F1414: 0 | G1414: 1 | H1414: 1 | I1414: 0.5 | J1414: 0 | K1414: Pastoral & Herding | L1414: Weide & Herde | M1414: 0 | N1414: 5 | O1414: 0 | P1414: By ʾhm is the {male camel} | Q1414: Um Ṣaḥab | R1414: ThSaf 74 | S1414: http://krc.orient.ox.ac.uk/ociana/corpus/pages/OCIANA_0018484.html
A1415: =B1415*Gewichtung!$B$2+C1415*Gewichtung!$B$3+D1415*Gewichtung!$B$4+E1415*Gewichtung!$B$5+F1415*Gewichtung!$B$6+G1415*Gewichtung!$B$7+H1415*Gewichtung!$B$8+I1415*Gewichtung!$B$9+J1415*Gewichtung!$B$10 -> 7.75 | B1415: 0 | C1415: 1 | D1415: 0 | E1415: 0 | F1415: 0 | G1415: 1 | H1415: 1 | I1415: 0.5 | J1415: 0 | K1415: Pastoral & Herding | L1415: Weide & Herde | M1415: 0 | N1415: 5 | O1415: 0 | P1415: By {s¹mr} is the young she-camel | Q1415: wadī and biyār al-ghuṣayn, Jordan | R1415: KhBG 414 | S1415: http://krc.orient.ox.ac.uk/ociana/corpus/pages/OCIANA_0018298.html
A1416: =B1416*Gewichtung!$B$2+C1416*Gewichtung!$B$3+D1416*Gewichtung!$B$4+E1416*Gewichtung!$B$5+F1416*Gewichtung!$B$6+G1416*Gewichtung!$B$7+H1416*Gewichtung!$B$8+I1416*Gewichtung!$B$9+J1416*Gewichtung!$B$10 -> 7.75 | B1416: 0 | C1416: 1 | D1416: 0 | E1416: 0 | F1416: 0 | G1416: 1 | H1416: 1 | I1416: 0.5 | J1416: 0 | K1416: Pastoral & Herding | L1416: Weide & Herde | M1416: 0 | N1416: 5 | O1416: 0 | P1416: By Wʿd is the {young she-camel} | Q1416: Ghadīr al-Darb, Al-Suwaydah, Syria | R1416: C 4659 | S1416: http://krc.orient.ox.ac.uk/ociana/corpus/pages/OCIANA_0007863.html
A1417: =B1417*Gewichtung!$B$2+C1417*Gewichtung!$B$3+D1417*Gewichtung!$B$4+E1417*Gewichtung!$B$5+F1417*Gewichtung!$B$6+G1417*Gewichtung!$B$7+H1417*Gewichtung!$B$8+I1417*Gewichtung!$B$9+J1417*Gewichtung!$B$10 -> 7.75 | B1417: 0 | C1417: 1 | D1417: 0 | E1417: 0 | F1417: 0 | G1417: 1 | H1417: 1 | I1417: 0.5 | J1417: 0 | K1417: Pastoral & Herding | L1417: Weide & Herde | M1417: 0 | N1417: 5 | O1417: 0 | P1417: By Qḥs² is the the {camel} | Q1417: — | R1417: Al-Namārah.H 148 | S1417: http://krc.orient.ox.ac.uk/ociana/corpus/pages/OCIANA_0026359.html
A1418: =B1418*Gewichtung!$B$2+C1418*Gewichtung!$B$3+D1418*Gewichtung!$B$4+E1418*Gewichtung!$B$5+F1418*Gewichtung!$B$6+G1418*Gewichtung!$B$7+H1418*Gewichtung!$B$8+I1418*Gewichtung!$B$9+J1418*Gewichtung!$B$10 -> 7.75 | B1418: 0 | C1418: 1 | D1418: 0 | E1418: 0 | F1418: 0 | G1418: 1 | H1418: 1 | I1418: 0.5 | J1418: 0 | K1418: Pastoral & Herding | L1418: Weide & Herde | M1418: 0 | N1418: 5 | O1418: 0 | P1418: By Ḍbʾt is the {young she-camel} | Q1418: Al-ʿĪsāwī, Rif Dimašq, Syria | R1418: Is.L 255 | S1418: http://krc.orient.ox.ac.uk/ociana/corpus/pages/OCIANA_0026661.html
A1419: =B1419*Gewichtung!$B$2+C1419*Gewichtung!$B$3+D1419*Gewichtung!$B$4+E1419*Gewichtung!$B$5+F1419*Gewichtung!$B$6+G1419*Gewichtung!$B$7+H1419*Gewichtung!$B$8+I1419*Gewichtung!$B$9+J1419*Gewichtung!$B$10 -> 7.75 | B1419: 0 | C1419: 1 | D1419: 0 | E1419: 0 | F1419: 0 | G1419: 1 | H1419: 1 | I1419: 0.5 | J1419: 0 | K1419: Pastoral & Herding | L1419: Weide & Herde | M1419: 0 | N1419: 5 | O1419: 0 | P1419: By {Ks¹m} is the male camel | Q1419: Site 14 | R1419: AbaNS 957 | S1419: http://krc.orient.ox.ac.uk/ociana/corpus/pages/OCIANA_0025736.html
A1420: =B1420*Gewichtung!$B$2+C1420*Gewichtung!$B$3+D1420*Gewichtung!$B$4+E1420*Gewichtung!$B$5+F1420*Gewichtung!$B$6+G1420*Gewichtung!$B$7+H1420*Gewichtung!$B$8+I1420*Gewichtung!$B$9+J1420*Gewichtung!$B$10 -> 7.75 | B1420: 0 | C1420: 1 | D1420: 0 | E1420: 0 | F1420: 0 | G1420: 1 | H1420: 1 | I1420: 0.5 | J1420: 0 | K1420: Pastoral & Herding | L1420: Weide & Herde | M1420: 0 | N1420: 5 | O1420: 0 | P1420: By ʾṯy is {the young she-camel} | Q1420: Site 14 | R1420: AbaNS 867 | S1420: http://krc.orient.ox.ac.uk/ociana/corpus/pages/OCIANA_0025643.html
... A2033: =B2033*Gewichtung!$B$2+C2033*Gewichtung!$B$3+D2033*Gewichtung!$B$4+E2033*Gewichtung!$B$5+F2033*Gewichtung!$B$6+G2033*Gewichtung!$B$7+H2033*Gewichtung!$B$8+I2033*Gewichtung!$B$9+J2033*Gewichtung!$B$10 -> 6.4 | B2033: 0 | C2033: 1 | D2033: 0 | E2033: 0 | F2033: 0 | G2033: 0.2 | H2033: 1 | I2033: 1 | J2033: 0.05 | K2033: Pastoral & Herding | L2033: Weide & Herde | M2033: 0 | N2033: 4 | O2033: 0 | P2033: By ʿbd son of ʾdm is the young she-camel | Q2033: Qāʿ Fahadah and Tell al-Fāhdawy, Al-Mafraq Province, Jordan | R2033: ASFF 344 | S2033: http://krc.orient.ox.ac.uk/ociana/corpus/pages/OCIANA_0034078.html
A2034: =B2034*Gewichtung!$B$2+C2034*Gewichtung!$B$3+D2034*Gewichtung!$B$4+E2034*Gewichtung!$B$5+F2034*Gewichtung!$B$6+G2034*Gewichtung!$B$7+H2034*Gewichtung!$B$8+I2034*Gewichtung!$B$9+J2034*Gewichtung!$B$10 -> 6.4 | B2034: 0 | C2034: 1 | D2034: 0 | E2034: 0 | F2034: 0 | G2034: 0.2 | H2034: 1 | I2034: 1 | J2034: 0.05 | K2034: Pastoral & Herding | L2034: Weide & Herde | M2034: 0 | N2034: 4 | O2034: 0 | P2034: By Mnʿ son of Hʾs¹ n S¹krn is the male camel | Q2034: Jordan | S2034: http://krc.orient.ox.ac.uk/ociana/corpus/pages/OCIANA_0034962.html
A2035: =B2035*Gewichtung!$B$2+C2035*Gewichtung!$B$3+D2035*Gewichtung!$B$4+E2035*Gewichtung!$B$5+F2035*Gewichtung!$B$6+G2035*Gewichtung!$B$7+H2035*Gewichtung!$B$8+I2035*Gewichtung!$B$9+J2035*Gewichtung!$B$10 -> 6.4 | B2035: 0 | C2035: 1 | D2035: 0 | E2035: 0 | F2035: 0 | G2035: 0.2 | H2035: 1 | I2035: 1 | J2035: 0.05 | K2035: Pastoral & Herding | L2035: Weide & Herde | M2035: 0 | N2035: 4 | O2035: 0 | P2035: By ʿwḏ son of Frhz is the male camel | Q2035: Wādī Salma, Al Mafraq Province, Jordan | R2035: HASI 1 | S2035: http://krc.orient.ox.ac.uk/ociana/corpus/pages/OCIANA_0034952.html
A2036: =B2036*Gewichtung!$B$2+C2036*Gewichtung!$B$3+D2036*Gewichtung!$B$4+E2036*Gewichtung!$B$5+F2036*Gewichtung!$B$6+G2036*Gewichtung!$B$7+H2036*Gewichtung!$B$8+I2036*Gewichtung!$B$9+J2036*Gewichtung!$B$10 -> 6.4 | B2036: 0 | C2036: 1 | D2036: 0 | E2036: 0 | F2036: 0 | G2036: 0.2 | H2036: 1 | I2036: 1 | J2036: 0.05 | K2036: Pastoral & Herding | L2036: Weide & Herde | M2036: 0 | N2036: 4 | O2036: 0 | P2036: By Yʿml son of Bṭnt is the male camel | Q2036: wadī and biyār al-ghuṣayn, Jordan | R2036: KhBG 51 | S2036: http://krc.orient.ox.ac.uk/ociana/corpus/pages/OCIANA_0017923.html
A2037: =B2037*Gewichtung!$B$2+C2037*Gewichtung!$B$3+D2037*Gewichtung!$B$4+E2037*Gewichtung!$B$5+F2037*Gewichtung!$B$6+G2037*Gewichtung!$B$7+H2037*Gewichtung!$B$8+I2037*Gewichtung!$B$9+J2037*Gewichtung!$B$10 -> 6.4 | B2037: 0 | C2037: 1 | D2037: 0 | E2037: 0 | F2037: 0 | G2037: 0.2 | H2037: 1 | I2037: 1 | J2037: 0.05 | K2037: Pastoral & Herding | L2037: Weide & Herde | M2037: 0 | N2037: 4 | O2037: 0 | P2037: By Yṯʿ son of Rg is the male camel | Q2037: Wādī Salma, Al-Mafraq Province, Jordan | R2037: RWQ 188 | S2037: http://krc.orient.ox.ac.uk/ociana/corpus/pages/OCIANA_0032116.html
A2038: =B2038*Gewichtung!$B$2+C2038*Gewichtung!$B$3+D2038*Gewichtung!$B$4+E2038*Gewichtung!$B$5+F2038*Gewichtung!$B$6+G2038*Gewichtung!$B$7+H2038*Gewichtung!$B$8+I2038*Gewichtung!$B$9+J2038*Gewichtung!$B$10 -> 6.4 | B2038: 0 | C2038: 1 | D2038: 0 | E2038: 0 | F2038: 0 | G2038: 0.2 | H2038: 1 | I2038: 1 | J2038: 0.05 | K2038: Pastoral & Herding | L2038: Weide & Herde | M2038: 0 | N2038: 4 | O2038: 0 | P2038: By Lbg son of S²ḥl is the young she-camel | Q2038: Wādī Salma, Al-Mafraq Province, Jordan | R2038: RWQ 171 | S2038: http://krc.orient.ox.ac.uk/ociana/corpus/pages/OCIANA_0032099.html
A2039: =B2039*Gewichtung!$B$2+C2039*Gewichtung!$B$3+D2039*Gewichtung!$B$4+E2039*Gewichtung!$B$5+F2039*Gewichtung!$B$6+G2039*Gewichtung!$B$7+H2039*Gewichtung!$B$8+I2039*Gewichtung!$B$9+J2039*Gewichtung!$B$10 -> 6.4 | B2039: 0 | C2039: 1 | D2039: 0 | E2039: 0 | F2039: 0 | G2039: 0.2 | H2039: 1 | I2039: 1 | J2039: 0.05 | K2039: Pastoral & Herding | L2039: Weide & Herde | M2039: 0 | N2039: 4 | O2039: 0 | P2039: By ʾgdl son of Ms¹k is the young she-camel | Q2039: Al-Namārah (C p. 443), Rif Dimashq, Syria | R2039: C 3620 | S2039: http://krc.orient.ox.ac.uk/ociana/corpus/pages/OCIANA_0006824.html
A2040: =B2040*Gewichtung!$B$2+C2040*Gewichtung!$B$3+D2040*Gewichtung!$B$4+E2040*Gewichtung!$B$5+F2040*Gewichtung!$B$6+G2040*Gewichtung!$B$7+H2040*Gewichtung!$B$8+I2040*Gewichtung!$B$9+J2040*Gewichtung!$B$10 -> 6.4 | B2040: 0 | C2040: 1 | D2040: 0 | E2040: 0 | F2040: 0 | G2040: 0.2 | H2040: 1 | I2040: 1 | J2040: 0.05 | K2040: Pastoral & Herding | L2040: Weide & Herde | M2040: 0 | N2040: 4 | O2040: 0 | P2040: By S²k son of Ġnṯ is the male camel | Q2040: — | R2040: WH 2009 | S2040: http://krc.orient.ox.ac.uk/ociana/corpus/pages/OCIANA_0012873.html
A2041: =B2041*Gewichtung!$B$2+C2041*Gewichtung!$B$3+D2041*Gewichtung!$B$4+E2041*Gewichtung!$B$5+F2041*Gewichtung!$B$6+G2041*Gewichtung!$B$7+H2041*Gewichtung!$B$8+I2041*Gewichtung!$B$9+J2041*Gewichtung!$B$10 -> 6.4 | B2041: 0 | C2041: 1 | D2041: 0 | E2041: 0 | F2041: 0 | G2041: 0.2 | H2041: 1 | I2041: 1 | J2041: 0.05 | K2041: Pastoral & Herding | L2041: Weide & Herde | M2041: 0 | N2041: 4 | O2041: 0 | P2041: By ʾḥlm son of ʿmdn is the young she-camel | Q2041: — | R2041: WH 2008 | S2041: http://krc.orient.ox.ac.uk/ociana/corpus/pages/OCIANA_0012872.html
A2042: =B2042*Gewichtung!$B$2+C2042*Gewichtung!$B$3+D2042*Gewichtung!$B$4+E2042*Gewichtung!$B$5+F2042*Gewichtung!$B$6+G2042*Gewichtung!$B$7+H2042*Gewichtung!$B$8+I2042*Gewichtung!$B$9+J2042*Gewichtung!$B$10 -> 6.4 | B2042: 0 | C2042: 1 | D2042: 0 | E2042: 0 | F2042: 0 | G2042: 0.2 | H2042: 1 | I2042: 1 | J2042: 0.05 | K2042: Pastoral & Herding | L2042: Weide & Herde | M2042: 0 | N2042: 4 | O2042: 0 | P2042: By S²kr son of Hf is the male camel | Q2042: Site 11 | R2042: AbaNS 341 | S2042: http://krc.orient.ox.ac.uk/ociana/corpus/pages/OCIANA_0025106.html
A2043: =B2043*Gewichtung!$B$2+C2043*Gewichtung!$B$3+D2043*Gewichtung!$B$4+E2043*Gewichtung!$B$5+F2043*Gewichtung!$B$6+G2043*Gewichtung!$B$7+H2043*Gewichtung!$B$8+I2043*Gewichtung!$B$9+J2043*Gewichtung!$B$10 -> 6.4 | B2043: 0 | C2043: 1 | D2043: 0 | E2043: 0 | F2043: 0 | G2043: 0.2 | H2043: 1 | I2043: 1 | J2043: 0.05 | K2043: Pastoral & Herding | L2043: Weide & Herde | M2043: 0 | N2043: 4 | O2043: 0 | P2043: By Gd son of S²gʿt is the male camel | Q2043: Site 11 | R2043: AbaNS 328 | S2043: http://krc.orient.ox.ac.uk/ociana/corpus/pages/OCIANA_0025093.html
A2044: =B2044*Gewichtung!$B$2+C2044*Gewichtung!$B$3+D2044*Gewichtung!$B$4+E2044*Gewichtung!$B$5+F2044*Gewichtung!$B$6+G2044*Gewichtung!$B$7+H2044*Gewichtung!$B$8+I2044*Gewichtung!$B$9+J2044*Gewichtung!$B$10 -> 6.4 | B2044: 0 | C2044: 1 | D2044: 0 | E2044: 0 | F2044: 0 | G2044: 0.2 | H2044: 1 | I2044: 1 | J2044: 0.05 | K2044: Pastoral & Herding | L2044: Weide & Herde | M2044: 0 | N2044: 4 | O2044: 0 | P2044: By Grt son of Ḫṭm is the young she-camel | Q2044: Cairn 39 | R2044: AbaNS 109 | S2044: http://krc.orient.ox.ac.uk/ociana/corpus/pages/OCIANA_0024869.html
A2045: =B2045*Gewichtung!$B$2+C2045*Gewichtung!$B$3+D2045*Gewichtung!$B$4+E2045*Gewichtung!$B$5+F2045*Gewichtung!$B$6+G2045*Gewichtung!$B$7+H2045*Gewichtung!$B$8+I2045*Gewichtung!$B$9+J2045*Gewichtung!$B$10 -> 6.4 | B2045: 0 | C2045: 1 | D2045: 0 | E2045: 0 | F2045: 0 | G2045: 0.2 | H2045: 1 | I2045: 1 | J2045: 0.05 | K2045: Pastoral & Herding | L2045: Weide & Herde | M2045: 0 | N2045: 4 | O2045: 0 | P2045: By ʿyt son of Mnʾl is the young she-camel | Q2045: Site 8 | R2045: AbaNS 315 | S2045: http://krc.orient.ox.ac.uk/ociana/corpus/pages/OCIANA_0025080.html
...
